File: steel.csv
Displacement (mm),Load (kN),Engineering Stress (GPa)
0.025399,0.0008,0.000161293
0.026251,0.0008,0.000161293
0.025399,0.0008,0.000161293
0.025399,0.0008,0.000161293
0.025058,0.0008,0.000161293
0.02574,0.0008,0.000161293
0.02574,0.0008,0.000161293
0.02574,0.0008,0.000161293
0.025911,0.0008,0.000161293
0.025569,0.0008,0.000161293
0.025229,0.0008,0.000161293
0.025229,0.00093,0.000187503
0.026081,0.00093,0.000187503
0.025569,0.00093,0.000187503
0.025399,0.00093,0.000187503
0.02574,0.00093,0.000187503
0.025399,0.00161,0.000324602
0.025229,0.00174,0.000350812
0.025229,0.00174,0.000350812
0.026081,0.00161,0.000324602
0.025399,0.00161,0.000324602
0.025569,0.00174,0.000350812
0.025569,0.00161,0.000324602
0.02574,0.00161,0.000324602
0.025058,0.00147,0.000296376
0.025911,0.00161,0.000324602
0.02574,0.00161,0.000324602
0.025569,0.00161,0.000324602
0.025058,0.00201,0.000405248
0.02574,0.00228,0.000459685
0.025399,0.00268,0.000540331
0.025229,0.00322,0.000649204
0.025569,0.00322,0.000649204
0.026081,0.00322,0.000649204
0.02574,0.00322,0.000649204
0.025058,0.00335,0.000675414
0.02574,0.00335,0.000675414
0.025229,0.00335,0.000675414
0.025569,0.00335,0.000675414
0.025058,0.00335,0.000675414
0.026081,0.00335,0.000675414
0.02574,0.00335,0.000675414
0.025058,0.00335,0.000675414
0.025229,0.00348,0.000701624
0.025399,0.00348,0.000701624
0.025569,0.00362,0.00072985
0.025569,0.00362,0.00072985
0.025399,0.00362,0.00072985
0.025569,0.00375,0.00075606
0.024888,0.00375,0.00075606
0.025229,0.00375,0.00075606
0.02574,0.00402,0.000810497
0.025569,0.00389,0.000784287
0.025229,0.00389,0.000784287
0.025399,0.00402,0.000810497
0.025569,0.00402,0.000810497
0.025229,0.00402,0.000810497
0.025569,0.00416,0.000838723
0.02574,0.00416,0.000838723
0.02574,0.00416,0.000838723
0.024717,0.00416,0.000838723
0.025399,0.00416,0.000838723
0.02574,0.00429,0.000864933
0.025229,0.00429,0.000864933
0.025399,0.00442,0.000891143
0.025399,0.00456,0.000919369
0.025569,0.00469,0.000945579
0.025058,0.00483,0.000973806
0.025058,0.00496,0.001000016
0.025911,0.00536,0.001080662
0.025569,0.00979,0.001973821
0.024717,0.01758,0.00354441
0.025058,0.02684,0.005411375
0.025399,0.03798,0.007657378
0.025229,0.05167,0.010417502
0.026251,0.06563,0.013232063
0.026933,0.08335,0.016804699
0.026593,0.10013,0.020187817
0.026933,0.12093,0.024381431
0.027445,0.14,0.02822625
0.028467,0.15758,0.03177066
0.028638,0.19006,0.03831915
0.028638,0.21073,0.042486554
0.029831,0.23718,0.047819299
0.029831,0.26255,0.052934299
0.030173,0.29852,0.060186429
0.031195,0.33288,0.067113957
0.032047,0.36724,0.074041485
0.032559,0.40483,0.081620233
0.032729,0.44966,0.090658681
0.033411,0.48859,0.098507595
0.034434,0.53503,0.107870645
0.034093,0.57637,0.116205453
0.035286,0.62389,0.125786249
0.035968,0.66926,0.13493357
0.036139,0.72134,0.145433735
0.03665,0.7659,0.154417747
0.037161,0.81879,0.165081221
0.038696,0.8663,0.17466
0.038525,0.91919,0.185323474
0.039548,0.96375,0.194307486
0.04057,1.01476,0.204591922
0.04023,1.06644,0.21501144
0.041082,1.11879,0.225566041
0.042276,1.15973,0.233820203
0.043128,1.22818,0.247620823
0.043638,1.27583,0.257227829
0.043638,1.33221,0.268594942
0.044492,1.37986,0.278201948
0.045344,1.43422,0.289161798
0.045684,1.48859,0.300123663
0.046878,1.54429,0.311353678
0.047048,1.59127,0.320825601
0.045684,1.62751,0.328132167
0.041082,1.57919,0.318390079
0.040912,1.61073,0.32474905
0.042104,1.62953,0.328539432
0.042276,1.64429,0.331515285
0.042104,1.65906,0.334493154
0.042616,1.67919,0.338551686
0.042104,1.68657,0.340039612
0.042276,1.68456,0.339634364
0.042786,1.67516,0.337739173
0.042616,1.6557,0.333815724
0.042616,1.63758,0.330162441
0.041594,1.63154,0.32894468
0.041764,1.62013,0.326644241
0.042446,1.60469,0.323531289
0.042276,1.59731,0.322043362
0.042446,1.58657,0.319878006
0.04432,1.57382,0.317307401
0.048923,1.56644,0.315819474
0.053527,1.55302,0.313113787
0.059663,1.55234,0.312976688
0.066822,1.53892,0.310271
0.073301,1.53154,0.308783073
0.079778,1.52147,0.3067528
0.08796,1.51006,0.30445236
0.09495,1.5,0.302424103
0.102621,1.49395,0.301204325
0.109952,1.47986,0.298363555
0.11677,1.47315,0.297010711
0.124441,1.46912,0.296198198
0.1316,1.45838,0.294032842
0.137566,1.45436,0.293222345
0.144897,1.45637,0.293627594
0.151033,1.45771,0.293897759
0.15666,1.46375,0.29511552
0.163137,1.46577,0.295522785
0.169445,1.46912,0.296198198
0.174558,1.47785,0.297958307
0.180866,1.48657,0.299716399
0.185809,1.4906,0.300528912
0.191947,1.50201,0.302829351
0.197912,1.50604,0.303641864
0.203368,1.51342,0.30512979
0.209674,1.5208,0.306617717
0.215641,1.5255,0.307565312
0.220755,1.53154,0.308783073
0.226722,1.53892,0.310271
0.232858,1.54228,0.31094843
0.237631,1.551,0.312706522
0.244791,1.55704,0.313924283
0.249734,1.55838,0.314194449
0.256212,1.56778,0.31608964
0.261497,1.57382,0.317307401
0.267122,1.57986,0.318525162
0.27377,1.58523,0.31960784
0.278032,1.59127,0.320825601
0.281101,1.59597,0.321773197
0.284681,1.60402,0.323396206
0.287237,1.60671,0.323938553
0.289113,1.61543,0.325696645
0.29184,1.61677,0.325966811
0.294738,1.62281,0.327184572
0.296272,1.62684,0.327997085
0.298318,1.63221,0.329079763
0.301386,1.63758,0.330162441
0.303943,1.64228,0.331110037
0.306159,1.64765,0.332192715
0.308717,1.65369,0.333410476
0.311785,1.65503,0.333680642
0.313489,1.66308,0.335303651
0.315876,1.66442,0.335573817
0.319114,1.67114,0.336928677
0.321842,1.67382,0.337469008
0.323718,1.67785,0.33828152
0.326445,1.68255,0.339229116
0.328831,1.68724,0.340174695
0.331899,1.6906,0.340852125
0.334457,1.69597,0.341934803
0.336843,1.69731,0.342204969
0.3394,1.70536,0.343827978
0.342128,1.70738,0.344235243
0.344684,1.71275,0.345317921
0.347753,1.71476,0.345723169
0.35031,1.72013,0.346805848
0.352867,1.72416,0.34761836
0.355083,1.72953,0.348701039
0.358151,1.7302,0.348836122
0.361391,1.73624,0.350053883
0.363948,1.73892,0.350594214
0.366334,1.74496,0.351811975
0.369062,1.74697,0.352217223
0.37196,1.75167,0.353164818
0.374517,1.75369,0.353572083
0.377245,1.75906,0.354654761
0.380483,1.75973,0.354789844
0.38304,1.76979,0.356818102
0.386108,1.77248,0.357360449
0.389178,1.77651,0.358172962
0.392586,1.77986,0.358848375
0.395825,1.7859,0.360066137
0.399235,1.78859,0.360608484
0.402643,1.7953,0.361961328
0.405883,1.79664,0.362231493
0.408951,1.80469,0.363854502
0.41219,1.80536,0.363989585
0.41611,1.8114,0.365207346
0.41952,1.81275,0.365479528
0.422759,1.82013,0.366967455
0.426169,1.82147,0.36723762
0.429577,1.82885,0.368725547
0.433328,1.83221,0.369402977
0.436226,1.83489,0.369943308
0.439806,1.83892,0.37075582
0.443215,1.84295,0.371568333
0.446455,1.84563,0.372108664
0.450205,1.85302,0.373598607
0.453955,1.85302,0.373598607
0.457876,1.86241,0.375491782
0.45958,1.86174,0.375356699
0.4635,1.86711,0.376439377
0.467763,1.86845,0.376709543
0.470491,1.87449,0.377927304
0.473387,1.87583,0.37819747
0.476797,1.88322,0.379687412
0.480718,1.88255,0.37955233
0.484128,1.88926,0.380905173
0.487196,1.88926,0.380905173
0.490605,1.89463,0.381987852
0.493163,1.89798,0.382663265
0.497595,1.90335,0.383745944
0.500833,1.90536,0.384151192
0.504754,1.9114,0.385368953
0.507822,1.9114,0.385368953
0.51038,1.91677,0.386451631
0.513959,1.91946,0.386993979
0.517539,1.92281,0.387669392
0.520777,1.92483,0.388076657
0.523846,1.9302,0.389159335
0.528108,1.93087,0.389294418
0.531346,1.93758,0.390647262
0.534244,1.93758,0.390647262
0.538336,1.94429,0.392000106
0.541745,1.94563,0.392270271
0.544985,1.94966,0.393082784
0.548223,1.95234,0.393623115
0.552144,1.95436,0.394030379
0.555724,1.95973,0.395113058
0.559645,1.96174,0.395518306
0.562883,1.96241,0.395653389
0.566633,1.96979,0.397141315
0.569873,1.96979,0.397141315
0.57277,1.97516,0.398223994
0.576692,1.97651,0.398496175
0.581294,1.98187,0.399576837
0.584021,1.9812,0.399441755
0.587261,1.9859,0.40038935
0.591181,1.98791,0.400794598
0.595443,1.99261,0.401742194
0.59834,1.99261,0.401742194
0.60209,1.99798,0.402824872
0.605841,2.00067,0.40336722
0.609251,2.00402,0.404042633
0.612319,2.00402,0.404042633
0.61641,2.0114,0.40553056
0.620502,2.01006,0.405260394
0.624252,2.01744,0.406748321
0.626979,2.0161,0.406478155
0.631071,2.02147,0.407560834
0.634821,2.02214,0.407695916
0.63823,2.02684,0.408643512
0.641298,2.02751,0.408778595
0.645048,2.03154,0.409591108
0.648799,2.03355,0.409996356
0.652549,2.03892,0.411079034
0.656641,2.03892,0.411079034
0.660391,2.04161,0.411621381
0.664141,2.04429,0.412161712
0.66755,2.0463,0.412566961
0.6713,2.05033,0.413379473
0.675733,2.05234,0.413784722
0.679143,2.05503,0.414327069
0.681869,2.05637,0.414597235
0.68562,2.06107,0.41554483
0.690394,2.06241,0.415814996
0.693802,2.06577,0.416492426
0.697553,2.06644,0.416627508
0.701303,2.07046,0.417438005
0.705053,2.07248,0.417845269
0.708463,2.07449,0.418250518
0.712554,2.07785,0.418927948
0.716646,2.08187,0.419738444
0.720396,2.08053,0.419468279
0.723464,2.08456,0.420280791
0.727555,2.08791,0.420956205
0.731987,2.0906,0.421498553
0.735396,2.09194,0.421768718
0.739146,2.09463,0.422311065
0.742897,2.09597,0.422581231
0.746307,2.09731,0.422851396
0.750057,2.10067,0.423528826
0.754148,2.10335,0.424069157
0.757898,2.10402,0.42420424
0.761308,2.10939,0.425286918
0.765399,2.11073,0.425557084
0.76949,2.11073,0.425557084
0.773923,2.11409,0.426234514
0.776991,2.11812,0.427047027
0.781082,2.11946,0.427317192
0.784492,2.11946,0.427317192
0.788242,2.12214,0.427857523
0.792333,2.12416,0.428264788
0.796083,2.12751,0.428940202
0.800175,2.1302,0.429482549
0.804266,2.13154,0.429752714
0.808016,2.13422,0.430293045
0.812448,2.13489,0.430428128
0.816539,2.13959,0.431375724
0.820289,2.13959,0.431375724
0.823699,2.14026,0.431510806
0.82779,2.14228,0.431918071
0.831882,2.14765,0.433000749
0.834608,2.1463,0.432728568
0.839382,2.151,0.433676163
0.843473,2.151,0.433676163
0.847905,2.15503,0.434488676
0.851656,2.15369,0.43421851
0.855746,2.15973,0.435436271
0.859838,2.15704,0.434893924
0.863589,2.15906,0.435301189
0.867339,2.16375,0.436246768
0.871429,2.16577,0.436654032
0.875521,2.16241,0.435976602
0.87893,2.16912,0.437329446
0.883022,2.16979,0.437464529
0.887454,2.17114,0.437736711
0.891885,2.17248,0.438006876
0.895295,2.17583,0.43868229
0.899046,2.17852,0.439224637
0.903818,2.17852,0.439224637
0.907569,2.17919,0.43935972
0.911319,2.18255,0.44003715
0.915069,2.18322,0.440172233
0.919501,2.18724,0.440982729
0.923934,2.18523,0.440577481
0.927342,2.18859,0.441254911
0.931434,2.19127,0.441795242
0.935867,2.19395,0.442335573
0.939957,2.19261,0.442065408
0.943708,2.19395,0.442335573
0.9478,2.19597,0.442742838
0.952572,2.19932,0.443418251
0.955982,2.19932,0.443418251
0.960073,2.20067,0.443690433
0.964164,2.20201,0.443960599
0.968938,2.20604,0.444773111
0.972688,2.20536,0.444636013
0.976779,2.20805,0.44517836
0.981893,2.20939,0.445448525
0.985983,2.21073,0.445718691
0.990075,2.2114,0.445853774
0.993484,2.21543,0.446666286
0.997916,2.21342,0.446261038
1.00269,2.21812,0.447208634
1.006441,2.21812,0.447208634
1.010191,2.22147,0.447884047
1.014622,2.22013,0.447613882
1.019396,2.22348,0.448289296
1.023487,2.2255,0.44869656
1.027578,2.22684,0.448966726
1.032011,2.22617,0.448831643
1.036442,2.22953,0.449509073
1.040192,2.22885,0.449371974
1.044624,2.23154,0.449914321
1.049398,2.23221,0.450049404
1.053489,2.23557,0.450726834
1.057239,2.23355,0.45031957
1.061672,2.24026,0.451672413
1.066444,2.23892,0.451402248
1.070195,2.23825,0.451267165
1.075309,2.24026,0.451672413
1.079741,2.24429,0.452484926
1.083832,2.24228,0.452079678
1.087924,2.2463,0.452890174
1.091674,2.24496,0.452620009
1.096447,2.24899,0.453432522
1.100879,2.24832,0.453297439
1.10497,2.251,0.45383777
1.109062,2.25033,0.453702687
1.114176,2.25302,0.454245034
1.118949,2.25234,0.454107935
1.123381,2.25637,0.454920448
1.127131,2.25302,0.454245034
1.131904,2.25838,0.455325696
1.136678,2.25838,0.455325696
1.140428,2.25838,0.455325696
1.144179,2.25771,0.455190614
1.148951,2.26375,0.456408375
1.153383,2.26375,0.456408375
1.158156,2.26577,0.456815639
1.162588,2.26241,0.456138209
1.167703,2.26711,0.457085805
1.171793,2.2651,0.456680556
1.175885,2.26845,0.45735597
1.180998,2.26845,0.45735597
1.185772,2.26979,0.457626136
1.189181,2.27046,0.457761219
1.193613,2.27382,0.458438649
1.198727,2.27449,0.458573731
1.2035,2.27449,0.458573731
1.207592,2.27382,0.458438649
1.212024,2.27785,0.459251161
1.216285,2.27651,0.458980996
1.2214,2.27919,0.459521327
1.225662,2.27919,0.459521327
1.229923,2.2812,0.459926575
1.234185,2.28053,0.459791492
1.239299,2.28389,0.460468922
1.243561,2.28187,0.460061658
1.248674,2.28523,0.460739088
1.252936,2.28523,0.460739088
1.258051,2.28791,0.461279419
1.262313,2.2859,0.460874171
1.266573,2.28859,0.461416518
1.271688,2.28926,0.461551601
1.277654,2.2906,0.461821766
1.281063,2.28791,0.461279419
1.285325,2.29328,0.462362097
1.290439,2.29463,0.462634279
1.295554,2.29463,0.462634279
1.298962,2.29328,0.462362097
1.304077,2.29664,0.463039527
1.309191,2.29597,0.462904444
1.314305,2.29865,0.463444776
1.318566,2.29865,0.463444776
1.322828,2.29932,0.463579858
1.327942,2.30067,0.46385204
1.332203,2.30067,0.46385204
1.337317,2.30067,0.46385204
1.342432,2.30335,0.464392371
1.346694,2.30335,0.464392371
1.351807,2.30536,0.464797619
1.356069,2.30738,0.465204884
1.362036,2.30536,0.464797619
1.366298,2.30604,0.464934718
1.370559,2.30738,0.465204884
1.375673,2.31006,0.465745215
1.380787,2.30805,0.465339967
1.385049,2.31073,0.465880298
1.390162,2.30939,0.465610132
1.396129,2.31409,0.466557728
1.400391,2.30939,0.465610132
1.405505,2.3161,0.466962976
1.409766,2.31208,0.466152479
1.41488,2.31476,0.46669281
1.420847,2.31476,0.46669281
1.424257,2.31677,0.467098059
1.42937,2.31409,0.466557728
1.434484,2.31879,0.467505323
1.439598,2.31744,0.467233141
1.44386,2.31879,0.467505323
1.448973,2.31812,0.46737024
1.45494,2.31946,0.467640406
1.459202,2.32013,0.467775489
1.464316,2.32147,0.468045654
1.469431,2.32013,0.467775489
1.474544,2.32214,0.468180737
1.479658,2.32348,0.468450903
1.48392,2.32416,0.468588001
1.489034,2.32348,0.468450903
1.495001,2.32617,0.46899325
1.499262,2.3255,0.468858167
1.504376,2.32818,0.469398498
1.50949,2.32483,0.468723084
1.515457,2.3255,0.468858167
1.519717,2.32751,0.469263415
1.52398,2.32818,0.469398498
1.530798,2.32885,0.469533581
1.535913,2.32818,0.469398498
1.540175,2.32818,0.469398498
1.544436,2.3302,0.469805763
1.550402,2.33087,0.469940845
1.555516,2.33154,0.470075928
1.560631,2.3302,0.469805763
1.566597,2.33557,0.470888441
1.571711,2.33087,0.469940845
1.576824,2.33221,0.470211011
1.581086,2.33288,0.470346094
1.587053,2.33557,0.470888441
1.592167,2.33422,0.470616259
1.597281,2.33624,0.471023524
1.602394,2.33489,0.470751342
1.608361,2.33691,0.471158606
1.613475,2.33422,0.470616259
1.61859,2.33825,0.471428772
1.623704,2.33624,0.471023524
1.628817,2.33758,0.471293689
1.634783,2.33624,0.471023524
1.639897,2.33892,0.471563855
1.645012,2.33691,0.471158606
1.650126,2.33959,0.471698937
1.656093,2.34026,0.47183402
1.660353,2.34161,0.472106202
1.66632,2.33892,0.471563855
1.672286,2.34093,0.471969103
1.678253,2.34093,0.471969103
1.682515,2.34429,0.472646533
1.688481,2.34093,0.471969103
1.694448,2.34295,0.472376367
1.699561,2.34228,0.472241285
1.704675,2.34496,0.472781616
1.709789,2.34228,0.472241285
1.716608,2.34563,0.472916698
1.721722,2.34161,0.472106202
1.725985,2.34765,0.473323963
1.732803,2.34295,0.472376367
1.738768,2.34429,0.472646533
1.74303,2.34429,0.472646533
1.748997,2.34765,0.473323963
1.754963,2.34429,0.472646533
1.76093,2.3463,0.473051781
1.765192,2.34295,0.472376367
1.772011,2.34765,0.473323963
1.777124,2.34563,0.472916698
1.78309,2.34765,0.473323963
1.788204,2.34429,0.472646533
1.795023,2.34563,0.472916698
1.800137,2.34697,0.473186864
1.806104,2.34697,0.473186864
1.811218,2.3463,0.473051781
1.817184,2.34697,0.473186864
1.823151,2.3463,0.473051781
1.829117,2.34832,0.473459046
1.835936,2.3463,0.473051781
1.840197,2.34697,0.473186864
1.846163,2.34765,0.473323963
1.852982,2.34765,0.473323963
1.857244,2.34563,0.472916698
1.86321,2.34966,0.473729211
1.869177,2.34832,0.473459046
1.875996,2.34832,0.473459046
1.880257,2.34697,0.473186864
1.887076,2.34697,0.473186864
1.892189,2.34697,0.473186864
1.899008,2.34899,0.473594128
1.904122,2.34563,0.472916698
1.910941,2.34832,0.473459046
1.916907,2.34697,0.473186864
1.922874,2.34765,0.473323963
1.92884,2.3463,0.473051781
1.934807,2.3463,0.473051781
1.939921,2.34496,0.472781616
1.94674,2.34832,0.473459046
1.952706,2.34563,0.472916698
1.958673,2.34765,0.473323963
1.964639,2.34496,0.472781616
1.971458,2.34563,0.472916698
1.976571,2.3463,0.473051781
1.983389,2.3463,0.473051781
1.989356,2.34362,0.47251145
1.996174,2.34563,0.472916698
2.001289,2.34563,0.472916698
2.007255,2.34362,0.47251145
2.013222,2.34295,0.472376367
2.02004,2.34429,0.472646533
2.026007,2.34295,0.472376367
2.031973,2.34496,0.472781616
2.039644,2.34362,0.47251145
2.04561,2.34161,0.472106202
2.051577,2.34093,0.471969103
2.057544,2.34093,0.471969103
2.064362,2.34161,0.472106202
2.071181,2.34026,0.47183402
2.077147,2.33959,0.471698937
2.084818,2.34026,0.47183402
2.090784,2.33825,0.471428772
2.096751,2.33758,0.471293689
2.102717,2.34026,0.47183402
2.109536,2.33422,0.470616259
2.116354,2.33758,0.471293689
2.124025,2.33221,0.470211011
2.128288,2.33691,0.471158606
2.135958,2.33087,0.469940845
2.141925,2.33221,0.470211011
2.147891,2.33087,0.469940845
2.15471,2.33221,0.470211011
2.161529,2.32617,0.46899325
2.168347,2.3302,0.469805763
2.175166,2.32617,0.46899325
2.181132,2.32751,0.469263415
2.188803,2.32348,0.468450903
2.194769,2.3255,0.468858167
2.201588,2.3208,0.467910571
2.207555,2.32147,0.468045654
2.213521,2.31946,0.467640406
2.221192,2.32147,0.468045654
2.22801,2.3161,0.466962976
2.233977,2.3161,0.466962976
2.241649,2.31275,0.466287562
2.248467,2.31409,0.466557728
2.254434,2.30872,0.465475049
2.260399,2.3114,0.46601538
2.268923,2.30738,0.465204884
2.275742,2.30805,0.465339967
2.282561,2.30201,0.464122206
2.287675,2.30201,0.464122206
2.294493,2.30268,0.464257288
2.302164,2.30067,0.46385204
2.308983,2.29731,0.46317461
2.315802,2.29664,0.463039527
2.32262,2.29395,0.46249718
2.329439,2.29328,0.462362097
2.336258,2.28859,0.461416518
2.342224,2.28926,0.461551601
2.349043,2.28389,0.460468922
2.355861,2.28456,0.460604005
2.36268,2.28187,0.460061658
2.370352,2.27986,0.45965641
2.377171,2.27651,0.458980996
2.383989,2.27651,0.458980996
2.390808,2.26979,0.457626136
2.397626,2.27382,0.458438649
2.404445,2.26644,0.456950722
2.412116,2.26442,0.456543458
2.41723,2.2604,0.455732961
2.424901,2.26241,0.456138209
2.430867,2.25436,0.4545152
2.438538,2.25838,0.455325696
2.444505,2.25033,0.453702687
2.452175,2.251,0.45383777
2.458994,2.24563,0.452755092
2.466666,2.24429,0.452484926
2.472631,2.23892,0.451402248
2.480304,2.23825,0.451267165
2.48627,2.23288,0.450184487
2.493941,2.23221,0.450049404
2.499907,2.22818,0.449236891
2.507578,2.2255,0.44869656
2.514397,2.22214,0.44801913
2.522067,2.21812,0.447208634
2.528034,2.21409,0.446396121
2.534853,2.21476,0.446531204
2.542523,2.20738,0.445043277
2.54849,2.20536,0.444636013
2.555308,2.20201,0.443960599
2.562127,2.19798,0.443148086
2.569799,2.1953,0.442607755
2.578322,2.18993,0.441525077
2.583436,2.18724,0.440982729
2.590255,2.18523,0.440577481
2.598778,2.17919,0.43935972
2.604744,2.17583,0.43868229
2.611563,2.17248,0.438006876
2.619234,2.16778,0.437059281
2.626052,2.16375,0.436246768
2.632871,2.1604,0.435571354
2.638838,2.15704,0.434893924
2.646508,2.15302,0.434083428
2.654181,2.14899,0.433270915
2.660999,2.14496,0.432458402
2.667818,2.13959,0.431375724
2.675488,2.13624,0.43070031
2.681455,2.13221,0.429887797
2.689126,2.12885,0.429210367
2.695944,2.12348,0.428127689
2.703615,2.11744,0.426909928
2.709582,2.11677,0.426774845
2.717252,2.11006,0.425422001
2.723219,2.10536,0.424474406
2.731743,2.10134,0.423663909
2.73771,2.09664,0.422716314
2.74538,2.08993,0.42136347
2.751347,2.09194,0.421768718
2.75987,2.07986,0.419333196
2.765836,2.07718,0.418792865
2.774359,2.07181,0.417710187
2.779474,2.06644,0.416627508
2.787144,2.06107,0.41554483
2.793963,2.06107,0.41554483
2.802487,2.05033,0.413379473
2.808454,2.04966,0.413244391
2.816124,2.04093,0.411484282
2.823795,2.03624,0.410538703
2.830614,2.02953,0.409185859
2.837433,2.02684,0.408643512
2.844251,2.01879,0.407020503
2.851922,2.01543,0.406343073
2.858741,2.00738,0.404720063
2.866413,2.00536,0.404312799
2.873231,1.99664,0.402554707
2.880902,1.9906,0.401336946
2.886868,1.98657,0.400524433
2.895391,1.98053,0.399306672
2.901358,1.97248,0.397683663
2.909881,1.96845,0.39687115
2.9167,1.9604,0.39524814
2.923518,1.95771,0.394705793
2.930338,1.94765,0.392677536
2.937157,1.94429,0.392000106
2.946532,1.93691,0.390512179
2.952498,1.92953,0.389024252
2.959317,1.92483,0.388076657
2.96784,1.91812,0.386723813
2.975512,1.90872,0.384828622
2.981477,1.90469,0.384016109
2.988297,1.8953,0.382122934
2.995968,1.89328,0.38171567
3.004491,1.88255,0.37955233
3.011309,1.87785,0.378604734
3.018128,1.86845,0.376709543
3.024095,1.86308,0.375626865
3.032618,1.8557,0.374138938
3.039436,1.84832,0.372651011
3.046256,1.84093,0.371161069
3.054779,1.83422,0.369808225
3.061598,1.82617,0.368185216
3.068416,1.8208,0.367102537
3.075235,1.81073,0.365072263
3.082053,1.80469,0.363854502
3.090577,1.79664,0.362231493
3.097395,1.78859,0.360608484
3.105919,1.77986,0.358848375
3.112738,1.77449,0.357765697
3.121261,1.76375,0.355600341
3.12808,1.75771,0.35438258
3.134898,1.74765,0.352354322
3.143423,1.74026,0.350864379
3.150241,1.73154,0.349106287
3.158764,1.72416,0.34761836
3.165583,1.71409,0.345588087
3.172401,1.70738,0.344235243
3.17922,1.69798,0.342340052
3.189448,1.68926,0.34058196
3.196267,1.67718,0.338146438
3.203086,1.66979,0.336656495
3.211609,1.66107,0.334898403
3.218427,1.64966,0.332597963
3.225246,1.64295,0.33124512
3.232065,1.63422,0.329485011
3.242293,1.62416,0.327456754
3.249112,1.61342,0.325291397
3.25593,1.60536,0.323666372
3.262749,1.59664,0.321908279
3.272978,1.58322,0.319202592
3.279797,1.57449,0.317442484
3.286615,1.56442,0.31541221
3.295138,1.55302,0.313113787
3.301957,1.54429,0.311353678
3.310481,1.53422,0.309323404
3.3173,1.52416,0.307295147
3.324118,1.51073,0.304587443
3.332641,1.50201,0.302829351
3.341164,1.4906,0.300528912
3.349688,1.48053,0.298498638
3.354801,1.46711,0.29579295
3.363325,1.45637,0.293627594
3.371849,1.44362,0.291056989
3.380371,1.43221,0.288756549
3.38719,1.42147,0.286591193
3.395714,1.40872,0.284020588
3.404238,1.39127,0.280502387
3.414466,1.35167,0.272518391